Workbook

Sheet Cover
A1: FY25 Dummy Accounting Workbook — July 2025
A3: Purpose | B3: Formula-linked accounting cycle from two raw bank statements
A4: Entity | B4: Truck It In (Private) Limited
A5: Currency | B5: PKR
A6: Period | B6: 01-Jul-2025 to 31-Jul-2025
A7: Model status | B7: =Checks!G3 -> Where to fix
A8: Blue font | B8: Editable inputs / mappings
A9: Green font | B9: Links to another worksheet
A11: Step | B11: Source | C11: Feeds | D11: What is formula-driven | E11: Manual review area | F11: Control
A12: 1 | B12: Chart of Accounts | C12: Mapping, Journal, GL, TB | D12: Account names and classifications | E12: Valid account structure | F12: All GL codes found
A13: 2 | B13: Raw bank statements | C13: Transaction Mapping | D13: Dates, references, debits, credits | E13: None—raw evidence remains unchanged | F13: Opening + credits − debits = closing
A14: 3 | B14: Transaction Mapping | C14: Journal Entries, Cash Flow | D14: GL names and transaction details | E14: Type, counterparty, tax, documents, GL selection | F14: All rows approved/matched
A15: 4 | B15: Non-Bank Entries | C15: Journal Entries | D15: Adjustment account names | E15: Accrual-basis adjustments | F15: Entry support and approval
A16: 5 | B16: Journal Entries | C16: General Ledger | D16: All posted lines | E16: Posting approval | F16: Debits = credits
A17: 6 | B17: General Ledger | C17: Trial Balance | D17: Account totals and balances | E17: None | F17: Ledger ties to journal
A18: 7 | B18: Trial Balance | C18: P&L and Balance Sheet | D18: Statement values | E18: None | F18: TB debits = credits
A19: 8 | B19: Mapping + statements | C19: Cash Flow and Checks | D19: Cash classifications and reconciliation | E19: None | F19: Ending cash ties everywhere

Sheet Chart of Accounts
A1: TRUCK IT IN PVT LTD
A2: Chart of Accounts
A3: FY25
J4: Opening | L4: Movement | N4: Adjustment | P4: Closing
A5: Nature | B5: Classification 1 | C5: Classification 2 | D5: Classification 3 | E5: Classification 4 | F5: Classification 5 | G5: Classification 7 | H5: Code | I5: Title | J5: Debit | K5: Credit | L5: Debit2 | M5: Credit3 | N5: Debit4 | O5: Credit5 | P5: Debit6 | Q5: Credit7 | R5: Column 1 | S5: Column 2
A6: B/S | B6: Assets | C6: Non Current Assets | D6: Property and equipment | E6: Cost | F6: Cost | G6: Furniture and fixture | H6: 1011 | I6: Furniture and fixture | P6: 0 | Q6: 0 | S6: People
A7: B/S | B7: Assets | C7: Non Current Assets | D7: Property and equipment | E7: Cost | F7: Cost | G7: Leasehold building | H7: 1012 | I7: Leasehold building | P7: 0 | Q7: 0 | S7: Travel & Entertainment
A8: B/S | B8: Assets | C8: Non Current Assets | D8: Property and equipment | E8: Cost | F8: Cost | G8: Computers | H8: 1013 | I8: Computers | P8: 0 | Q8: 0 | S8: Travel & Entertainment
A9: B/S | B9: Assets | C9: Non Current Assets | D9: Property and equipment | E9: Cost | F9: Cost | G9: Office Equipments | H9: 1014 | I9: Office Equipments | P9: 0 | Q9: 0 | S9: Travel & Entertainment
A10: B/S | B10: Assets | C10: Non Current Assets | D10: Property and equipment | E10: Cost | F10: Cost | G10: Vehicles | H10: 1015 | I10: Vehicles | P10: 0 | Q10: 0 | S10: Travel & Entertainment
A11: B/S | B11: Assets | C11: Non Current Assets | D11: Intanbgible assets | E11: Cost | F11: Cost | G11: Intangible Assets | H11: 1016 | I11: Intangible Assets | P11: 0 | Q11: 0 | S11: Travel & Entertainment
A12: B/S | B12: Assets | C12: Non Current Assets | D12: Property and equipment | E12: Accumulated Depreciation | F12: Accumulated Depreciation | G12: Accumulated depreciation | H12: 1017 | I12: Accumulated depreciation | P12: 0 | Q12: 0 | S12: Travel & Entertainment
A13: B/S | B13: Assets | C13: Current Assets | D13: Trade debts | E13: unsecured | F13: Considered good | G13: Trade Debtors | H13: 1018 | I13: Trade Debtors | P13: 0 | Q13: 0 | S13: Travel & Entertainment
A14: B/S | B14: Assets | C14: Current Assets | D14: Advances, deposits and prepayments | E14: Advances | F14: Carriers | G14: Advance to carriers | H14: 1019 | I14: Advance to carriers | P14: 0 | Q14: 0 | S14: Travel & Entertainment
A15: B/S | B15: Assets | C15: Non Current Assets | D15: Long term advances and deposits | E15: Advances | F15: To employees | G15: Advance to BYOD | H15: 1020 | I15: Advance to BYOD | P15: 0 | Q15: 0 | S15: Travel & Entertainment
A16: B/S | B16: Assets | C16: Non Current Assets | D16: Long term advances and deposits | E16: Deposits | F16: Security deposit office | G16: Security deposit-Office | H16: 1021 | I16: Security deposit-Office | P16: 0 | Q16: 0 | S16: Real Estate
A17: B/S | B17: Assets | C17: Current Assets | D17: Advances, deposits and prepayments | E17: Deposits | F17: Customers | G17: Security Deposits - Customer | H17: 1022 | I17: Security Deposits - Customer | P17: 0 | Q17: 0 | S17: Profit
... A67: P&L | B67: Expenses | C67: Taxation | D67: Final tax levy | E67: Final tax levy | F67: Final tax levy | G67: Final tax levy | H67: New code 3 | I67: Final tax levy | P67: 0 | Q67: 0 | S67: People

Sheet HBL Operating Account
A1: HBL — Raw Bank Statement
A2: Account title | B2: Truck It In (Private) Limited | F2: Opening balance | G2: 3250000
A3: Account number | B3: PK55HABB0022827200508103 | F3: Total debits | G3: =SUM(E8:E41) -> 3437724
A4: Statement period | B4: 01-Jul-2025 to 31-Jul-2025 | F4: Total credits | G4: =SUM(F8:F41) -> 4185650
A5: Currency | B5: PKR | F5: Closing balance | G5: =G2-G3+G4 -> 3997926
A7: Transaction Date | B7: Value Date | C7: Description | D7: Reference | E7: Debit (PKR) | F7: Credit (PKR) | G7: Balance (PKR)
A8: 45839 | B8: 45839 | C8: IBFT CR - Daraz Pakistan settlement INV-DZ-250701 | D8: HBL250701001 | F8: 685000 | G8: =$G$2-E8+F8 -> 3935000
A9: 45839 | B9: 45839 | C9: Online transfer - Office rent July - Blue Area Properties | D9: HBL250701002 | E9: 275000 | G9: =G8-E9+F9 -> 3660000
A10: 45840 | B10: 45840 | C10: Raast CR - Onic distribution collection Batch 0702 | D10: HBL250702003 | F10: 412500 | G10: =G9-E10+F10 -> 4072500
A11: 45840 | B11: 45840 | C11: POS 7712 - Shell F-8 Islamabad | D11: HBL250702004 | E11: 18450 | G11: =G10-E11+F11 -> 4054050
A12: 45841 | B12: 45841 | C12: Cheque 104583 - Pak Cargo Fleet Services | D12: CHQ104583 | E12: 335000 | G12: =G11-E12+F12 -> 3719050
A13: 45841 | B13: 45841 | C13: Withholding tax on cheque 104583 | D13: WHT104583 | E13: 3350 | G13: =G12-E13+F13 -> 3715700
A14: 45842 | B14: 45842 | C14: IBFT CR - Sapphire merchant COD settlement | D14: HBL250704007 | F14: 298750 | G14: =G13-E14+F14 -> 4014450
A15: 45842 | B15: 45842 | C15: Online payment - PTCL corporate internet June | D15: HBL250704008 | E15: 42800 | G15: =G14-E15+F15 -> 3971650
A16: 45843 | B16: 45843 | C16: ATM cash withdrawal - HBL Blue Area | D16: ATM250705 | E16: 50000 | G16: =G15-E16+F16 -> 3921650
A17: 45845 | B17: 45845 | C17: Transfer to Meezan Bank payroll account | D17: HBL250707011 | E17: 850000 | G17: =G16-E17+F17 -> 3071650
A18: 45846 | B18: 45846 | C18: IBFT CR - Merchant advance repayment - Saeed Ghani | D18: HBL250708012 | F18: 175000 | G18: =G17-E18+F18 -> 3246650
A19: 45846 | B19: 45846 | C19: Online transfer - Vehicle maintenance - Toyota Islamabad | D19: HBL250708013 | E19: 96750 | G19: =G18-E19+F19 -> 3149900
A20: 45847 | B20: 45847 | C20: Card 8821 - Microsoft 365 Business subscription | D20: HBL250709014 | E20: 36500 | G20: =G19-E20+F20 -> 3113400
A21: 45847 | B21: 45847 | C21: Foreign transaction fee - Microsoft subscription | D21: HBL250709015 | E21: 1095 | G21: =G20-E21+F21 -> 3112305
A22: 45848 | B22: 45848 | C22: Cash deposit - Islamabad operations collections | D22: CD250710 | F22: 224000 | G22: =G21-E22+F22 -> 3336305
A23: 45849 | B23: 45849 | C23: Cheque 104584 - Warehouse security deposit | D23: CHQ104584 | E23: 200000 | G23: =G22-E23+F23 -> 3136305
A24: 45850 | B24: 45850 | C24: IBFT CR - Daraz Pakistan settlement INV-DZ-250712 | D24: HBL250712018 | F24: 742500 | G24: =G23-E24+F24 -> 3878805
A25: 45852 | B25: 45852 | C25: Online transfer - Diesel supplier - PSO Fleet Card | D25: HBL250714019 | E25: 386200 | G25: =G24-E25+F25 -> 3492605
A26: 45853 | B26: 45853 | C26: Bank service charges - July | D26: HBL250715020 | E26: 2500 | G26: =G25-E26+F26 -> 3490105
A27: 45853 | B27: 45853 | C27: FED on bank service charges | D27: HBL250715021 | E27: 400 | G27: =G26-E27+F27 -> 3489705
A28: 45854 | B28: 45854 | C28: Raast CR - Corporate delivery customer AR-1098 | D28: HBL250716022 | F28: 455000 | G28: =G27-E28+F28 -> 3944705
A29: 45855 | B29: 45855 | C29: Online payment - Jazz corporate mobile bill | D29: HBL250717023 | E29: 58750 | G29: =G28-E29+F29 -> 3885955
A30: 45856 | B30: 45856 | C30: Cheque 104585 - Packaging material supplier | D30: CHQ104585 | E30: 148600 | G30: =G29-E30+F30 -> 3737355
A31: 45857 | B31: 45857 | C31: IBFT CR - Onic distribution collection Batch 0719 | D31: HBL250719025 | F31: 520000 | G31: =G30-E31+F31 -> 4257355
A32: 45859 | B32: 45859 | C32: Transfer to Meezan Bank payroll account | D32: HBL250721026 | E32: 550000 | G32: =G31-E32+F32 -> 3707355
A33: 45860 | B33: 45860 | C33: Online transfer - Insurance premium - EFU General | D33: HBL250722027 | E33: 180000 | G33: =G32-E33+F33 -> 3527355
A34: 45861 | B34: 45861 | C34: IBFT CR - COD settlement - Retail merchant pool | D34: HBL250723028 | F34: 389450 | G34: =G33-E34+F34 -> 3916805
A35: 45862 | B35: 45862 | C35: Card 8821 - AWS cloud services | D35: HBL250724029 | E35: 72600 | G35: =G34-E35+F35 -> 3844205
A36: 45863 | B36: 45863 | C36: Cheque return charges - customer cheque 77891 | D36: HBL250725030 | E36: 1500 | G36: =G35-E36+F36 -> 3842705
A37: 45866 | B37: 45866 | C37: IBFT CR - Customer cheque 77891 redeposited | D37: HBL250728031 | F37: 265000 | G37: =G36-E37+F37 -> 4107705
A38: 45867 | B38: 45867 | C38: Online transfer - Legal and professional fee | D38: HBL250729032 | E38: 125000 | G38: =G37-E38+F38 -> 3982705
A39: 45868 | B39: 45868 | C39: Profit credited on current-plus account | D39: HBL250730033 | F39: 18450 | G39: =G38-E39+F39 -> 4001155
A40: 45869 | B40: 45869 | C40: Zakat deduction on profit account | D40: HBL250731034 | E40: 461 | G40: =G39-E40+F40 -> 4000694
A41: 45869 | B41: 45869 | C41: Advance tax on bank profit | D41: HBL250731035 | E41: 2768 | G41: =G40-E41+F41 -> 3997926

Sheet Meezan Payroll Account
A1: Meezan Bank — Raw Bank Statement
A2: Account title | B2: Truck It In (Private) Limited | F2: Opening balance | G2: 480000
A3: Account number | B3: PK24MEZN0001110107095251 | F3: Total debits | G3: =SUM(E8:E32) -> 1875588
A4: Statement period | B4: 01-Jul-2025 to 31-Jul-2025 | F4: Total credits | G4: =SUM(F8:F32) -> 1454500
A5: Currency | B5: PKR | F5: Closing balance | G5: =G2-G3+G4 -> 58912
A7: Transaction Date | B7: Value Date | C7: Description | D7: Reference | E7: Debit (PKR) | F7: Credit (PKR) | G7: Balance (PKR)
A8: 45839 | B8: 45839 | C8: Opening-month cash deposit - payroll adjustments | D8: MBL250701001 | F8: 25000 | G8: =$G$2-E8+F8 -> 505000
A9: 45840 | B9: 45840 | C9: IBFT - Employee reimbursement - A. Khan | D9: MBL250702002 | E9: 18500 | G9: =G8-E9+F9 -> 486500
A10: 45841 | B10: 45841 | C10: IBFT - Rider incentive batch 01 | D10: MBL250703003 | E10: 96500 | G10: =G9-E10+F10 -> 390000
A11: 45842 | B11: 45842 | C11: Online payment - EOBI contribution June | D11: MBL250704004 | E11: 68400 | G11: =G10-E11+F11 -> 321600
A12: 45843 | B12: 45843 | C12: Online payment - Social Security contribution June | D12: MBL250705005 | E12: 42750 | G12: =G11-E12+F12 -> 278850
A13: 45845 | B13: 45845 | C13: Incoming IBFT from HBL operating account | D13: MBL250707006 | F13: 850000 | G13: =G12-E13+F13 -> 1128850
A14: 45845 | B14: 45845 | C14: Bulk salary transfer - July payroll batch A | D14: PAY250707A | E14: 625000 | G14: =G13-E14+F14 -> 503850
A15: 45845 | B15: 45845 | C15: Payroll processing charges | D15: MBL250707008 | E15: 3750 | G15: =G14-E15+F15 -> 500100
A16: 45845 | B16: 45845 | C16: FED on payroll processing charges | D16: MBL250707009 | E16: 600 | G16: =G15-E16+F16 -> 499500
A17: 45846 | B17: 45846 | C17: IBFT - Employee advance - M. Usman | D17: MBL250708010 | E17: 30000 | G17: =G16-E17+F17 -> 469500
A18: 45848 | B18: 45848 | C18: Bulk transfer - Contract drivers settlement W27 | D18: MBL250710011 | E18: 156000 | G18: =G17-E18+F18 -> 313500
A19: 45849 | B19: 45849 | C19: Raast reversal - failed driver payment W27 | D19: MBL250711012 | F19: 12000 | G19: =G18-E19+F19 -> 325500
A20: 45850 | B20: 45850 | C20: Raast retry - driver payment W27 | D20: MBL250712013 | E20: 12000 | G20: =G19-E20+F20 -> 313500
A21: 45852 | B21: 45852 | C21: IBFT - Staff travel advance - Lahore operations | D21: MBL250714014 | E21: 45000 | G21: =G20-E21+F21 -> 268500
A22: 45854 | B22: 45854 | C22: Cash deposit - unused staff advance returned | D22: CD250716 | F22: 7500 | G22: =G21-E22+F22 -> 276000
A23: 45856 | B23: 45856 | C23: Bulk transfer - Contract drivers settlement W28 | D23: MBL250718016 | E23: 142500 | G23: =G22-E23+F23 -> 133500
A24: 45859 | B24: 45859 | C24: Incoming IBFT from HBL operating account | D24: MBL250721017 | F24: 550000 | G24: =G23-E24+F24 -> 683500
A25: 45859 | B25: 45859 | C25: Bulk salary transfer - July payroll batch B | D25: PAY250721B | E25: 245000 | G25: =G24-E25+F25 -> 438500
A26: 45860 | B26: 45860 | C26: IBFT - Employee medical reimbursement | D26: MBL250722019 | E26: 22000 | G26: =G25-E26+F26 -> 416500
A27: 45862 | B27: 45862 | C27: Bulk transfer - Contract drivers settlement W29 | D27: MBL250724020 | E27: 138000 | G27: =G26-E27+F27 -> 278500
A28: 45863 | B28: 45863 | C28: Raast CR - employee advance recovery | D28: MBL250725021 | F28: 10000 | G28: =G27-E28+F28 -> 288500
A29: 45866 | B29: 45866 | C29: IBFT - Final settlement - Former employee | D29: MBL250728022 | E29: 78500 | G29: =G28-E29+F29 -> 210000
A30: 45867 | B30: 45867 | C30: Bulk transfer - Contract drivers settlement W30 | D30: MBL250729023 | E30: 149000 | G30: =G29-E30+F30 -> 61000
A31: 45869 | B31: 45869 | C31: Bank service charges - July | D31: MBL250731024 | E31: 1800 | G31: =G30-E31+F31 -> 59200
A32: 45869 | B32: 45869 | C32: FED on bank service charges | D32: MBL250731025 | E32: 288 | G32: =G31-E32+F32 -> 58912

Sheet Transaction Mapping
A1: Transaction Mapping and Review
A2: Map ID | B2: Bank | C2: Date | D2: Description | E2: Reference | F2: Debit | G2: Credit | H2: Transaction Type | I2: Counterparty | J2: Supporting Document | K2: Bank GL Code | L2: Bank GL Name | M2: Offset GL Code | N2: Offset GL Name | O2: Tax Treatment | P2: Entity | Q2: Review Status | R2: Transfer Match ID | S2: Posting Status | T2: Cash Flow Category
A3: MAP-001 | B3: HBL | C3: ='HBL Operating Account'!A8 -> 45839 | D3: ='HBL Operating Account'!C8 -> IBFT CR - Daraz Pakistan settlement INV-DZ-250701 | E3: ='HBL Operating Account'!D8 -> HBL250701001 | F3: ='HBL Operating Account'!E8 | G3: ='HBL Operating Account'!F8 -> 685000 | H3: Customer receipt | I3: Daraz Pakistan | J3: Invoice INV-DZ-250701 | K3: 1029 | L3: {=IFERROR(XLOOKUP(K3,'Chart of Accounts'!$H$6:$H$67,'Chart of Accounts'!$I$6:$I$67),"GL not found")} -> GL not found | M3: 1018 | N3: {=IFERROR(XLOOKUP(M3,'Chart of Accounts'!$H$6:$H$67,'Chart of Accounts'!$I$6:$I$67),"GL not found")} -> GL not found | O3: N/A | P3: Truck It In (Private) Limited | Q3: Approved | S3: Post | T3: Operating - Receipts
A4: MAP-002 | B4: HBL | C4: ='HBL Operating Account'!A9 -> 45839 | D4: ='HBL Operating Account'!C9 -> Online transfer - Office rent July - Blue Area Properties | E4: ='HBL Operating Account'!D9 -> HBL250701002 | F4: ='HBL Operating Account'!E9 -> 275000 | G4: ='HBL Operating Account'!F9 | H4: Rent payment | I4: Blue Area Properties | J4: Lease/rent invoice | K4: 1029 | L4: {=IFERROR(XLOOKUP(K4,'Chart of Accounts'!$H$6:$H$67,'Chart of Accounts'!$I$6:$I$67),"GL not found")} -> GL not found | M4: 1058 | N4: {=IFERROR(XLOOKUP(M4,'Chart of Accounts'!$H$6:$H$67,'Chart of Accounts'!$I$6:$I$67),"GL not found")} -> GL not found | O4: Input tax review | P4: Truck It In (Private) Limited | Q4: Approved | S4: Post | T4: Operating - Payments
A5: MAP-003 | B5: HBL | C5: ='HBL Operating Account'!A10 -> 45840 | D5: ='HBL Operating Account'!C10 -> Raast CR - Onic distribution collection Batch 0702 | E5: ='HBL Operating Account'!D10 -> HBL250702003 | F5: ='HBL Operating Account'!E10 | G5: ='HBL Operating Account'!F10 -> 412500 | H5: Customer receipt | I5: Onic | J5: Collection batch 0702 | K5: 1029 | L5: {=IFERROR(XLOOKUP(K5,'Chart of Accounts'!$H$6:$H$67,'Chart of Accounts'!$I$6:$I$67),"GL not found")} -> GL not found | M5: 1018 | N5: {=IFERROR(XLOOKUP(M5,'Chart of Accounts'!$H$6:$H$67,'Chart of Accounts'!$I$6:$I$67),"GL not found")} -> GL not found | O5: N/A | P5: Truck It In (Private) Limited | Q5: Approved | S5: Post | T5: Operating - Receipts
A6: MAP-004 | B6: HBL | C6: ='HBL Operating Account'!A11 -> 45840 | D6: ='HBL Operating Account'!C11 -> POS 7712 - Shell F-8 Islamabad | E6: ='HBL Operating Account'!D11 -> HBL250702004 | F6: ='HBL Operating Account'!E11 -> 18450 | G6: ='HBL Operating Account'!F11 | H6: Fuel expense | I6: Shell Pakistan | J6: POS slip 7712 | K6: 1029 | L6: {=IFERROR(XLOOKUP(K6,'Chart of Accounts'!$H$6:$H$67,'Chart of Accounts'!$I$6:$I$67),"GL not found")} -> GL not found | M6: 1055 | N6: {=IFERROR(XLOOKUP(M6,'Chart of Accounts'!$H$6:$H$67,'Chart of Accounts'!$I$6:$I$67),"GL not found")} -> GL not found | O6: Input tax review | P6: Truck It In (Private) Limited | Q6: Approved | S6: Post | T6: Operating - Payments
A7: MAP-005 | B7: HBL | C7: ='HBL Operating Account'!A12 -> 45841 | D7: ='HBL Operating Account'!C12 -> Cheque 104583 - Pak Cargo Fleet Services | E7: ='HBL Operating Account'!D12 -> CHQ104583 | F7: ='HBL Operating Account'!E12 -> 335000 | G7: ='HBL Operating Account'!F12 | H7: Carrier payment | I7: Pak Cargo Fleet Services | J7: Vendor bill + cheque | K7: 1029 | L7: {=IFERROR(XLOOKUP(K7,'Chart of Accounts'!$H$6:$H$67,'Chart of Accounts'!$I$6:$I$67),"GL not found")} -> GL not found | M7: 1054 | N7: {=IFERROR(XLOOKUP(M7,'Chart of Accounts'!$H$6:$H$67,'Chart of Accounts'!$I$6:$I$67),"GL not found")} -> GL not found | O7: WHT applicable | P7: Truck It In (Private) Limited | Q7: Approved | S7: Post | T7: Operating - Payments
A8: MAP-006 | B8: HBL | C8: ='HBL Operating Account'!A13 -> 45841 | D8: ='HBL Operating Account'!C13 -> Withholding tax on cheque 104583 | E8: ='HBL Operating Account'!D13 -> WHT104583 | F8: ='HBL Operating Account'!E13 -> 3350 | G8: ='HBL Operating Account'!F13 | H8: Vendor withholding tax | I8: FBR | J8: WHT challan / vendor bill | K8: 1029 | L8: {=IFERROR(XLOOKUP(K8,'Chart of Accounts'!$H$6:$H$67,'Chart of Accounts'!$I$6:$I$67),"GL not found")} -> GL not found | M8: 1036 | N8: {=IFERROR(XLOOKUP(M8,'Chart of Accounts'!$H$6:$H$67,'Chart of Accounts'!$I$6:$I$67),"GL not found")} -> GL not found | O8: Withholding tax | P8: Truck It In (Private) Limited | Q8: Approved | S8: Post | T8: Operating - Payments
A9: MAP-007 | B9: HBL | C9: ='HBL Operating Account'!A14 -> 45842 | D9: ='HBL Operating Account'!C14 -> IBFT CR - Sapphire merchant COD settlement | E9: ='HBL Operating Account'!D14 -> HBL250704007 | F9: ='HBL Operating Account'!E14 | G9: ='HBL Operating Account'!F14 -> 298750 | H9: Customer receipt | I9: Sapphire | J9: COD settlement report | K9: 1029 | L9: {=IFERROR(XLOOKUP(K9,'Chart of Accounts'!$H$6:$H$67,'Chart of Accounts'!$I$6:$I$67),"GL not found")} -> GL not found | M9: 1018 | N9: {=IFERROR(XLOOKUP(M9,'Chart of Accounts'!$H$6:$H$67,'Chart of Accounts'!$I$6:$I$67),"GL not found")} -> GL not found | O9: N/A | P9: Truck It In (Private) Limited | Q9: Approved | S9: Post | T9: Operating - Receipts
A10: MAP-008 | B10: HBL | C10: ='HBL Operating Account'!A15 -> 45842 | D10: ='HBL Operating Account'!C15 -> Online payment - PTCL corporate internet June | E10: ='HBL Operating Account'!D15 -> HBL250704008 | F10: ='HBL Operating Account'!E15 -> 42800 | G10: ='HBL Operating Account'!F15 | H10: Utility payment | I10: PTCL | J10: PTCL invoice | K10: 1029 | L10: {=IFERROR(XLOOKUP(K10,'Chart of Accounts'!$H$6:$H$67,'Chart of Accounts'!$I$6:$I$67),"GL not found")} -> GL not found | M10: 1058 | N10: {=IFERROR(XLOOKUP(M10,'Chart of Accounts'!$H$6:$H$67,'Chart of Accounts'!$I$6:$I$67),"GL not found")} -> GL not found | O10: Input tax review | P10: Truck It In (Private) Limited | Q10: Approved | S10: Post | T10: Operating - Payments
A11: MAP-009 | B11: HBL | C11: ='HBL Operating Account'!A16 -> 45843 | D11: ='HBL Operating Account'!C16 -> ATM cash withdrawal - HBL Blue Area | E11: ='HBL Operating Account'!D16 -> ATM250705 | F11: ='HBL Operating Account'!E16 -> 50000 | G11: ='HBL Operating Account'!F16 | H11: Petty cash withdrawal | I11: Petty Cash Custodian | J11: Cash withdrawal slip | K11: 1029 | L11: {=IFERROR(XLOOKUP(K11,'Chart of Accounts'!$H$6:$H$67,'Chart of Accounts'!$I$6:$I$67),"GL not found")} -> GL not found | M11: 1068 | N11: {=IFERROR(XLOOKUP(M11,'Chart of Accounts'!$H$6:$H$67,'Chart of Accounts'!$I$6:$I$67),"GL not found")} -> GL not found | O11: N/A | P11: Truck It In (Private) Limited | Q11: Approved | S11: Post | T11: Operating - Payments
A12: MAP-010 | B12: HBL | C12: ='HBL Operating Account'!A17 -> 45845 | D12: ='HBL Operating Account'!C17 -> Transfer to Meezan Bank payroll account | E12: ='HBL Operating Account'!D17 -> HBL250707011 | F12: ='HBL Operating Account'!E17 -> 850000 | G12: ='HBL Operating Account'!F17 | H12: Inter-bank transfer | I12: Meezan Payroll Account | J12: Transfer pair TRF-0707 | K12: 1029 | L12: {=IFERROR(XLOOKUP(K12,'Chart of Accounts'!$H$6:$H$67,'Chart of Accounts'!$I$6:$I$67),"GL not found")} -> GL not found | M12: 1030 | N12: {=IFERROR(XLOOKUP(M12,'Chart of Accounts'!$H$6:$H$67,'Chart of Accounts'!$I$6:$I$67),"GL not found")} -> GL not found | O12: N/A | P12: Truck It In (Private) Limited | Q12: Approved | R12: TRF-0707 | S12: Post | T12: Transfer
A13: MAP-011 | B13: HBL | C13: ='HBL Operating Account'!A18 -> 45846 | D13: ='HBL Operating Account'!C18 -> IBFT CR - Merchant advance repayment - Saeed Ghani | E13: ='HBL Operating Account'!D18 -> HBL250708012 | F13: ='HBL Operating Account'!E18 | G13: ='HBL Operating Account'!F18 -> 175000 | H13: Customer receipt | I13: Saeed Ghani | J13: Merchant settlement advice | K13: 1029 | L13: {=IFERROR(XLOOKUP(K13,'Chart of Accounts'!$H$6:$H$67,'Chart of Accounts'!$I$6:$I$67),"GL not found")} -> GL not found | M13: 1018 | N13: {=IFERROR(XLOOKUP(M13,'Chart of Accounts'!$H$6:$H$67,'Chart of Accounts'!$I$6:$I$67),"GL not found")} -> GL not found | O13: N/A | P13: Truck It In (Private) Limited | Q13: Approved | S13: Post | T13: Operating - Receipts
A14: MAP-012 | B14: HBL | C14: ='HBL Operating Account'!A19 -> 45846 | D14: ='HBL Operating Account'!C19 -> Online transfer - Vehicle maintenance - Toyota Islamabad | E14: ='HBL Operating Account'!D19 -> HBL250708013 | F14: ='HBL Operating Account'!E19 -> 96750 | G14: ='HBL Operating Account'!F19 | H14: Vehicle maintenance | I14: Toyota Islamabad | J14: Workshop invoice | K14: 1029 | L14: {=IFERROR(XLOOKUP(K14,'Chart of Accounts'!$H$6:$H$67,'Chart of Accounts'!$I$6:$I$67),"GL not found")} -> GL not found | M14: 1068 | N14: {=IFERROR(XLOOKUP(M14,'Chart of Accounts'!$H$6:$H$67,'Chart of Accounts'!$I$6:$I$67),"GL not found")} -> GL not found | O14: Input tax review | P14: Truck It In (Private) Limited | Q14: Approved | S14: Post | T14: Operating - Payments
A15: MAP-013 | B15: HBL | C15: ='HBL Operating Account'!A20 -> 45847 | D15: ='HBL Operating Account'!C20 -> Card 8821 - Microsoft 365 Business subscription | E15: ='HBL Operating Account'!D20 -> HBL250709014 | F15: ='HBL Operating Account'!E20 -> 36500 | G15: ='HBL Operating Account'!F20 | H15: Software subscription | I15: Microsoft | J15: Microsoft invoice | K15: 1029 | L15: {=IFERROR(XLOOKUP(K15,'Chart of Accounts'!$H$6:$H$67,'Chart of Accounts'!$I$6:$I$67),"GL not found")} -> GL not found | M15: 1068 | N15: {=IFERROR(XLOOKUP(M15,'Chart of Accounts'!$H$6:$H$67,'Chart of Accounts'!$I$6:$I$67),"GL not found")} -> GL not found | O15: Reverse charge review | P15: Truck It In (Private) Limited | Q15: Approved | S15: Post | T15: Operating - Payments
A16: MAP-014 | B16: HBL | C16: ='HBL Operating Account'!A21 -> 45847 | D16: ='HBL Operating Account'!C21 -> Foreign transaction fee - Microsoft subscription | E16: ='HBL Operating Account'!D21 -> HBL250709015 | F16: ='HBL Operating Account'!E21 -> 1095 | G16: ='HBL Operating Account'!F21 | H16: Bank fee | I16: HBL | J16: Bank statement | K16: 1029 | L16: {=IFERROR(XLOOKUP(K16,'Chart of Accounts'!$H$6:$H$67,'Chart of Accounts'!$I$6:$I$67),"GL not found")} -> GL not found | M16: 1057 | N16: {=IFERROR(XLOOKUP(M16,'Chart of Accounts'!$H$6:$H$67,'Chart of Accounts'!$I$6:$I$67),"GL not found")} -> GL not found | O16: N/A | P16: Truck It In (Private) Limited | Q16: Approved | S16: Post | T16: Operating - Payments
A17: MAP-015 | B17: HBL | C17: ='HBL Operating Account'!A22 -> 45848 | D17: ='HBL Operating Account'!C22 -> Cash deposit - Islamabad operations collections | E17: ='HBL Operating Account'!D22 -> CD250710 | F17: ='HBL Operating Account'!E22 | G17: ='HBL Operating Account'!F22 -> 224000 | H17: Operations collection | I17: Islamabad Operations | J17: Daily collection sheet | K17: 1029 | L17: {=IFERROR(XLOOKUP(K17,'Chart of Accounts'!$H$6:$H$67,'Chart of Accounts'!$I$6:$I$67),"GL not found")} -> GL not found | M17: 1050 | N17: {=IFERROR(XLOOKUP(M17,'Chart of Accounts'!$H$6:$H$67,'Chart of Accounts'!$I$6:$I$67),"GL not found")} -> GL not found | O17: Output tax review | P17: Truck It In (Private) Limited | Q17: Approved | S17: Post | T17: Operating - Receipts
A18: MAP-016 | B18: HBL | C18: ='HBL Operating Account'!A23 -> 45849 | D18: ='HBL Operating Account'!C23 -> Cheque 104584 - Warehouse security deposit | E18: ='HBL Operating Account'!D23 -> CHQ104584 | F18: ='HBL Operating Account'!E23 -> 200000 | G18: ='HBL Operating Account'!F23 | H18: Security deposit | I18: Warehouse landlord | J18: Deposit agreement | K18: 1029 | L18: {=IFERROR(XLOOKUP(K18,'Chart of Accounts'!$H$6:$H$67,'Chart of Accounts'!$I$6:$I$67),"GL not found")} -> GL not found | M18: 1021 | N18: {=IFERROR(XLOOKUP(M18,'Chart of Accounts'!$H$6:$H$67,'Chart of Accounts'!$I$6:$I$67),"GL not found")} -> GL not found | O18: N/A | P18: Truck It In (Private) Limited | Q18: Approved | S18: Post | T18: Investing - Payments
A19: MAP-017 | B19: HBL | C19: ='HBL Operating Account'!A24 -> 45850 | D19: ='HBL Operating Account'!C24 -> IBFT CR - Daraz Pakistan settlement INV-DZ-250712 | E19: ='HBL Operating Account'!D24 -> HBL250712018 | F19: ='HBL Operating Account'!E24 | G19: ='HBL Operating Account'!F24 -> 742500 | H19: Customer receipt | I19: Daraz Pakistan | J19: Invoice INV-DZ-250712 | K19: 1029 | L19: {=IFERROR(XLOOKUP(K19,'Chart of Accounts'!$H$6:$H$67,'Chart of Accounts'!$I$6:$I$67),"GL not found")} -> GL not found | M19: 1018 | N19: {=IFERROR(XLOOKUP(M19,'Chart of Accounts'!$H$6:$H$67,'Chart of Accounts'!$I$6:$I$67),"GL not found")} -> GL not found | O19: N/A | P19: Truck It In (Private) Limited | Q19: Approved | S19: Post | T19: Operating - Receipts
A20: MAP-018 | B20: HBL | C20: ='HBL Operating Account'!A25 -> 45852 | D20: ='HBL Operating Account'!C25 -> Online transfer - Diesel supplier - PSO Fleet Card | E20: ='HBL Operating Account'!D25 -> HBL250714019 | F20: ='HBL Operating Account'!E25 -> 386200 | G20: ='HBL Operating Account'!F25 | H20: Fuel expense | I20: PSO | J20: Fleet card statement | K20: 1029 | L20: {=IFERROR(XLOOKUP(K20,'Chart of Accounts'!$H$6:$H$67,'Chart of Accounts'!$I$6:$I$67),"GL not found")} -> GL not found | M20: 1055 | N20: {=IFERROR(XLOOKUP(M20,'Chart of Accounts'!$H$6:$H$67,'Chart of Accounts'!$I$6:$I$67),"GL not found")} -> GL not found | O20: Input tax review | P20: Truck It In (Private) Limited | Q20: Approved | S20: Post | T20: Operating - Payments
A21: MAP-019 | B21: HBL | C21: ='HBL Operating Account'!A26 -> 45853 | D21: ='HBL Operating Account'!C26 -> Bank service charges - July | E21: ='HBL Operating Account'!D26 -> HBL250715020 | F21: ='HBL Operating Account'!E26 -> 2500 | G21: ='HBL Operating Account'!F26 | H21: Bank fee | I21: HBL | J21: Bank statement | K21: 1029 | L21: {=IFERROR(XLOOKUP(K21,'Chart of Accounts'!$H$6:$H$67,'Chart of Accounts'!$I$6:$I$67),"GL not found")} -> GL not found | M21: 1057 | N21: {=IFERROR(XLOOKUP(M21,'Chart of Accounts'!$H$6:$H$67,'Chart of Accounts'!$I$6:$I$67),"GL not found")} -> GL not found | O21: N/A | P21: Truck It In (Private) Limited | Q21: Approved | S21: Post | T21: Operating - Payments
A22: MAP-020 | B22: HBL | C22: ='HBL Operating Account'!A27 -> 45853 | D22: ='HBL Operating Account'!C27 -> FED on bank service charges | E22: ='HBL Operating Account'!D27 -> HBL250715021 | F22: ='HBL Operating Account'!E27 -> 400 | G22: ='HBL Operating Account'!F27 | H22: Federal excise duty | I22: FBR / HBL | J22: Bank statement | K22: 1029 | L22: {=IFERROR(XLOOKUP(K22,'Chart of Accounts'!$H$6:$H$67,'Chart of Accounts'!$I$6:$I$67),"GL not found")} -> GL not found | M22: 1068 | N22: {=IFERROR(XLOOKUP(M22,'Chart of Accounts'!$H$6:$H$67,'Chart of Accounts'!$I$6:$I$67),"GL not found")} -> GL not found | O22: FED expense | P22: Truck It In (Private) Limited | Q22: Approved | S22: Post | T22: Operating - Payments
A23: MAP-021 | B23: HBL | C23: ='HBL Operating Account'!A28 -> 45854 | D23: ='HBL Operating Account'!C28 -> Raast CR - Corporate delivery customer AR-1098 | E23: ='HBL Operating Account'!D28 -> HBL250716022 | F23: ='HBL Operating Account'!E28 | G23: ='HBL Operating Account'!F28 -> 455000 | H23: Customer receipt | I23: Corporate customer | J23: Invoice AR-1098 | K23: 1029 | L23: {=IFERROR(XLOOKUP(K23,'Chart of Accounts'!$H$6:$H$67,'Chart of Accounts'!$I$6:$I$67),"GL not found")} -> GL not found | M23: 1018 | N23: {=IFERROR(XLOOKUP(M23,'Chart of Accounts'!$H$6:$H$67,'Chart of Accounts'!$I$6:$I$67),"GL not found")} -> GL not found | O23: N/A | P23: Truck It In (Private) Limited | Q23: Approved | S23: Post | T23: Operating - Receipts
A24: MAP-022 | B24: HBL | C24: ='HBL Operating Account'!A29 -> 45855 | D24: ='HBL Operating Account'!C29 -> Online payment - Jazz corporate mobile bill | E24: ='HBL Operating Account'!D29 -> HBL250717023 | F24: ='HBL Operating Account'!E29 -> 58750 | G24: ='HBL Operating Account'!F29 | H24: Utility payment | I24: Jazz | J24: Jazz invoice | K24: 1029 | L24: {=IFERROR(XLOOKUP(K24,'Chart of Accounts'!$H$6:$H$67,'Chart of Accounts'!$I$6:$I$67),"GL not found")} -> GL not found | M24: 1058 | N24: {=IFERROR(XLOOKUP(M24,'Chart of Accounts'!$H$6:$H$67,'Chart of Accounts'!$I$6:$I$67),"GL not found")} -> GL not found | O24: Input tax review | P24: Truck It In (Private) Limited | Q24: Approved | S24: Post | T24: Operating - Payments
... A26: MAP-024 | B26: HBL | C26: ='HBL Operating Account'!A31 -> 45857 | D26: ='HBL Operating Account'!C31 -> IBFT CR - Onic distribution collection Batch 0719 | E26: ='HBL Operating Account'!D31 -> HBL250719025 | F26: ='HBL Operating Account'!E31 | G26: ='HBL Operating Account'!F31 -> 520000 | H26: Customer receipt | I26: Onic | J26: Collection batch 0719 | K26: 1029 | L26: {=IFERROR(XLOOKUP(K26,'Chart of Accounts'!$H$6:$H$67,'Chart of Accounts'!$I$6:$I$67),"GL not found")} -> GL not found | M26: 1018 | N26: {=IFERROR(XLOOKUP(M26,'Chart of Accounts'!$H$6:$H$67,'Chart of Accounts'!$I$6:$I$67),"GL not found")} -> GL not found | O26: N/A | P26: Truck It In (Private) Limited | Q26: Approved | S26: Post | T26: Operating - Receipts
A27: MAP-025 | B27: HBL | C27: ='HBL Operating Account'!A32 -> 45859 | D27: ='HBL Operating Account'!C32 -> Transfer to Meezan Bank payroll account | E27: ='HBL Operating Account'!D32 -> HBL250721026 | F27: ='HBL Operating Account'!E32 -> 550000 | G27: ='HBL Operating Account'!F32 | H27: Inter-bank transfer | I27: Meezan Payroll Account | J27: Transfer pair TRF-0721 | K27: 1029 | L27: {=IFERROR(XLOOKUP(K27,'Chart of Accounts'!$H$6:$H$67,'Chart of Accounts'!$I$6:$I$67),"GL not found")} -> GL not found | M27: 1030 | N27: {=IFERROR(XLOOKUP(M27,'Chart of Accounts'!$H$6:$H$67,'Chart of Accounts'!$I$6:$I$67),"GL not found")} -> GL not found | O27: N/A | P27: Truck It In (Private) Limited | Q27: Approved | R27: TRF-0721 | S27: Post | T27: Transfer
A28: MAP-026 | B28: HBL | C28: ='HBL Operating Account'!A33 -> 45860 | D28: ='HBL Operating Account'!C33 -> Online transfer - Insurance premium - EFU General | E28: ='HBL Operating Account'!D33 -> HBL250722027 | F28: ='HBL Operating Account'!E33 -> 180000 | G28: ='HBL Operating Account'!F33 | H28: Insurance prepayment | I28: EFU General | J28: Insurance policy | K28: 1029 | L28: {=IFERROR(XLOOKUP(K28,'Chart of Accounts'!$H$6:$H$67,'Chart of Accounts'!$I$6:$I$67),"GL not found")} -> GL not found | M28: 1026 | N28: {=IFERROR(XLOOKUP(M28,'Chart of Accounts'!$H$6:$H$67,'Chart of Accounts'!$I$6:$I$67),"GL not found")} -> GL not found | O28: N/A | P28: Truck It In (Private) Limited | Q28: Approved | S28: Post | T28: Operating - Payments
A29: MAP-027 | B29: HBL | C29: ='HBL Operating Account'!A34 -> 45861 | D29: ='HBL Operating Account'!C34 -> IBFT CR - COD settlement - Retail merchant pool | E29: ='HBL Operating Account'!D34 -> HBL250723028 | F29: ='HBL Operating Account'!E34 | G29: ='HBL Operating Account'!F34 -> 389450 | H29: Customer receipt | I29: Retail merchant pool | J29: COD settlement report | K29: 1029 | L29: {=IFERROR(XLOOKUP(K29,'Chart of Accounts'!$H$6:$H$67,'Chart of Accounts'!$I$6:$I$67),"GL not found")} -> GL not found | M29: 1018 | N29: {=IFERROR(XLOOKUP(M29,'Chart of Accounts'!$H$6:$H$67,'Chart of Accounts'!$I$6:$I$67),"GL not found")} -> GL not found | O29: N/A | P29: Truck It In (Private) Limited | Q29: Approved | S29: Post | T29: Operating - Receipts
A30: MAP-028 | B30: HBL | C30: ='HBL Operating Account'!A35 -> 45862 | D30: ='HBL Operating Account'!C35 -> Card 8821 - AWS cloud services | E30: ='HBL Operating Account'!D35 -> HBL250724029 | F30: ='HBL Operating Account'!E35 -> 72600 | G30: ='HBL Operating Account'!F35 | H30: Cloud services | I30: Amazon Web Services | J30: AWS invoice | K30: 1029 | L30: {=IFERROR(XLOOKUP(K30,'Chart of Accounts'!$H$6:$H$67,'Chart of Accounts'!$I$6:$I$67),"GL not found")} -> GL not found | M30: 1068 | N30: {=IFERROR(XLOOKUP(M30,'Chart of Accounts'!$H$6:$H$67,'Chart of Accounts'!$I$6:$I$67),"GL not found")} -> GL not found | O30: Reverse charge review | P30: Truck It In (Private) Limited | Q30: Approved | S30: Post | T30: Operating - Payments
A31: MAP-029 | B31: HBL | C31: ='HBL Operating Account'!A36 -> 45863 | D31: ='HBL Operating Account'!C36 -> Cheque return charges - customer cheque 77891 | E31: ='HBL Operating Account'!D36 -> HBL250725030 | F31: ='HBL Operating Account'!E36 -> 1500 | G31: ='HBL Operating Account'!F36 | H31: Bank fee | I31: HBL | J31: Bank statement | K31: 1029 | L31: {=IFERROR(XLOOKUP(K31,'Chart of Accounts'!$H$6:$H$67,'Chart of Accounts'!$I$6:$I$67),"GL not found")} -> GL not found | M31: 1057 | N31: {=IFERROR(XLOOKUP(M31,'Chart of Accounts'!$H$6:$H$67,'Chart of Accounts'!$I$6:$I$67),"GL not found")} -> GL not found | O31: N/A | P31: Truck It In (Private) Limited | Q31: Approved | S31: Post | T31: Operating - Payments
A32: MAP-030 | B32: HBL | C32: ='HBL Operating Account'!A37 -> 45866 | D32: ='HBL Operating Account'!C37 -> IBFT CR - Customer cheque 77891 redeposited | E32: ='HBL Operating Account'!D37 -> HBL250728031 | F32: ='HBL Operating Account'!E37 | G32: ='HBL Operating Account'!F37 -> 265000 | H32: Customer receipt | I32: Customer 77891 | J32: Cheque / deposit slip | K32: 1029 | L32: {=IFERROR(XLOOKUP(K32,'Chart of Accounts'!$H$6:$H$67,'Chart of Accounts'!$I$6:$I$67),"GL not found")} -> GL not found | M32: 1018 | N32: {=IFERROR(XLOOKUP(M32,'Chart of Accounts'!$H$6:$H$67,'Chart of Accounts'!$I$6:$I$67),"GL not found")} -> GL not found | O32: N/A | P32: Truck It In (Private) Limited | Q32: Approved | S32: Post | T32: Operating - Receipts
A33: MAP-031 | B33: HBL | C33: ='HBL Operating Account'!A38 -> 45867 | D33: ='HBL Operating Account'!C38 -> Online transfer - Legal and professional fee | E33: ='HBL Operating Account'!D38 -> HBL250729032 | F33: ='HBL Operating Account'!E38 -> 125000 | G33: ='HBL Operating Account'!F38 | H33: Professional fee | I33: Legal Adviser | J33: Professional invoice | K33: 1029 | L33: {=IFERROR(XLOOKUP(K33,'Chart of Accounts'!$H$6:$H$67,'Chart of Accounts'!$I$6:$I$67),"GL not found")} -> GL not found | M33: 1060 | N33: {=IFERROR(XLOOKUP(M33,'Chart of Accounts'!$H$6:$H$67,'Chart of Accounts'!$I$6:$I$67),"GL not found")} -> GL not found | O33: WHT review | P33: Truck It In (Private) Limited | Q33: Approved | S33: Post | T33: Operating - Payments
A34: MAP-032 | B34: HBL | C34: ='HBL Operating Account'!A39 -> 45868 | D34: ='HBL Operating Account'!C39 -> Profit credited on current-plus account | E34: ='HBL Operating Account'!D39 -> HBL250730033 | F34: ='HBL Operating Account'!E39 | G34: ='HBL Operating Account'!F39 -> 18450 | H34: Bank profit | I34: HBL | J34: Bank statement | K34: 1029 | L34: {=IFERROR(XLOOKUP(K34,'Chart of Accounts'!$H$6:$H$67,'Chart of Accounts'!$I$6:$I$67),"GL not found")} -> GL not found | M34: 1066 | N34: {=IFERROR(XLOOKUP(M34,'Chart of Accounts'!$H$6:$H$67,'Chart of Accounts'!$I$6:$I$67),"GL not found")} -> GL not found | O34: Advance tax review | P34: Truck It In (Private) Limited | Q34: Approved | S34: Post | T34: Operating - Receipts
A35: MAP-033 | B35: HBL | C35: ='HBL Operating Account'!A40 -> 45869 | D35: ='HBL Operating Account'!C40 -> Zakat deduction on profit account | E35: ='HBL Operating Account'!D40 -> HBL250731034 | F35: ='HBL Operating Account'!E40 -> 461 | G35: ='HBL Operating Account'!F40 | H35: Zakat expense | I35: HBL | J35: Bank statement | K35: 1029 | L35: {=IFERROR(XLOOKUP(K35,'Chart of Accounts'!$H$6:$H$67,'Chart of Accounts'!$I$6:$I$67),"GL not found")} -> GL not found | M35: 1068 | N35: {=IFERROR(XLOOKUP(M35,'Chart of Accounts'!$H$6:$H$67,'Chart of Accounts'!$I$6:$I$67),"GL not found")} -> GL not found | O35: N/A | P35: Truck It In (Private) Limited | Q35: Approved | S35: Post | T35: Operating - Payments
A36: MAP-034 | B36: HBL | C36: ='HBL Operating Account'!A41 -> 45869 | D36: ='HBL Operating Account'!C41 -> Advance tax on bank profit | E36: ='HBL Operating Account'!D41 -> HBL250731035 | F36: ='HBL Operating Account'!E41 -> 2768 | G36: ='HBL Operating Account'!F41 | H36: Advance tax | I36: FBR / HBL | J36: Bank statement | K36: 1029 | L36: {=IFERROR(XLOOKUP(K36,'Chart of Accounts'!$H$6:$H$67,'Chart of Accounts'!$I$6:$I$67),"GL not found")} -> GL not found | M36: 1045 | N36: {=IFERROR(XLOOKUP(M36,'Chart of Accounts'!$H$6:$H$67,'Chart of Accounts'!$I$6:$I$67),"GL not found")} -> GL not found | O36: Advance income tax | P36: Truck It In (Private) Limited | Q36: Approved | S36: Post | T36: Operating - Payments
A37: MAP-035 | B37: Meezan | C37: ='Meezan Payroll Account'!A8 -> 45839 | D37: ='Meezan Payroll Account'!C8 -> Opening-month cash deposit - payroll adjustments | E37: ='Meezan Payroll Account'!D8 -> MBL250701001 | F37: ='Meezan Payroll Account'!E8 | G37: ='Meezan Payroll Account'!F8 -> 25000 | H37: Payroll adjustment deposit | I37: Payroll Custodian | J37: Deposit slip | K37: 1030 | L37: {=IFERROR(XLOOKUP(K37,'Chart of Accounts'!$H$6:$H$67,'Chart of Accounts'!$I$6:$I$67),"GL not found")} -> GL not found | M37: 1034 | N37: {=IFERROR(XLOOKUP(M37,'Chart of Accounts'!$H$6:$H$67,'Chart of Accounts'!$I$6:$I$67),"GL not found")} -> GL not found | O37: N/A | P37: Truck It In (Private) Limited | Q37: Approved | S37: Post | T37: Operating - Receipts
A38: MAP-036 | B38: Meezan | C38: ='Meezan Payroll Account'!A9 -> 45840 | D38: ='Meezan Payroll Account'!C9 -> IBFT - Employee reimbursement - A. Khan | E38: ='Meezan Payroll Account'!D9 -> MBL250702002 | F38: ='Meezan Payroll Account'!E9 -> 18500 | G38: ='Meezan Payroll Account'!F9 | H38: Employee reimbursement | I38: A. Khan | J38: Expense claim | K38: 1030 | L38: {=IFERROR(XLOOKUP(K38,'Chart of Accounts'!$H$6:$H$67,'Chart of Accounts'!$I$6:$I$67),"GL not found")} -> GL not found | M38: 1068 | N38: {=IFERROR(XLOOKUP(M38,'Chart of Accounts'!$H$6:$H$67,'Chart of Accounts'!$I$6:$I$67),"GL not found")} -> GL not found | O38: N/A | P38: Truck It In (Private) Limited | Q38: Approved | S38: Post | T38: Operating - Payments
A39: MAP-037 | B39: Meezan | C39: ='Meezan Payroll Account'!A10 -> 45841 | D39: ='Meezan Payroll Account'!C10 -> IBFT - Rider incentive batch 01 | E39: ='Meezan Payroll Account'!D10 -> MBL250703003 | F39: ='Meezan Payroll Account'!E10 -> 96500 | G39: ='Meezan Payroll Account'!F10 | H39: Rider incentives | I39: Riders | J39: Incentive register | K39: 1030 | L39: {=IFERROR(XLOOKUP(K39,'Chart of Accounts'!$H$6:$H$67,'Chart of Accounts'!$I$6:$I$67),"GL not found")} -> GL not found | M39: 1056 | N39: {=IFERROR(XLOOKUP(M39,'Chart of Accounts'!$H$6:$H$67,'Chart of Accounts'!$I$6:$I$67),"GL not found")} -> GL not found | O39: Payroll | P39: Truck It In (Private) Limited | Q39: Approved | S39: Post | T39: Operating - Payments
A40: MAP-038 | B40: Meezan | C40: ='Meezan Payroll Account'!A11 -> 45842 | D40: ='Meezan Payroll Account'!C11 -> Online payment - EOBI contribution June | E40: ='Meezan Payroll Account'!D11 -> MBL250704004 | F40: ='Meezan Payroll Account'!E11 -> 68400 | G40: ='Meezan Payroll Account'!F11 | H40: Payroll liability payment | I40: EOBI | J40: EOBI challan | K40: 1030 | L40: {=IFERROR(XLOOKUP(K40,'Chart of Accounts'!$H$6:$H$67,'Chart of Accounts'!$I$6:$I$67),"GL not found")} -> GL not found | M40: 1034 | N40: {=IFERROR(XLOOKUP(M40,'Chart of Accounts'!$H$6:$H$67,'Chart of Accounts'!$I$6:$I$67),"GL not found")} -> GL not found | O40: Payroll statutory | P40: Truck It In (Private) Limited | Q40: Approved | S40: Post | T40: Operating - Payments
A41: MAP-039 | B41: Meezan | C41: ='Meezan Payroll Account'!A12 -> 45843 | D41: ='Meezan Payroll Account'!C12 -> Online payment - Social Security contribution June | E41: ='Meezan Payroll Account'!D12 -> MBL250705005 | F41: ='Meezan Payroll Account'!E12 -> 42750 | G41: ='Meezan Payroll Account'!F12 | H41: Payroll liability payment | I41: Social Security | J41: Contribution challan | K41: 1030 | L41: {=IFERROR(XLOOKUP(K41,'Chart of Accounts'!$H$6:$H$67,'Chart of Accounts'!$I$6:$I$67),"GL not found")} -> GL not found | M41: 1034 | N41: {=IFERROR(XLOOKUP(M41,'Chart of Accounts'!$H$6:$H$67,'Chart of Accounts'!$I$6:$I$67),"GL not found")} -> GL not found | O41: Payroll statutory | P41: Truck It In (Private) Limited | Q41: Approved | S41: Post | T41: Operating - Payments
...

Sheet Non-Bank Entries
A1: Non-Bank Journal Entries
A2: Entry ID | B2: Date | C2: Description | D2: Debit GL | E2: Debit Account | F2: Credit GL | G2: Credit Account | H2: Amount | I2: Tax Treatment | J2: Entity | K2: Supporting Document | L2: Review Status | M2: Cash Flow Impact
A3: NB-001 | B3: 45869 | C3: Unpaid customer invoice - July services | D3: 1018 | E3: {=IFERROR(XLOOKUP(D3,'Chart of Accounts'!$H$6:$H$67,'Chart of Accounts'!$I$6:$I$67),"GL not found")} -> GL not found | F3: 1050 | G3: {=IFERROR(XLOOKUP(F3,'Chart of Accounts'!$H$6:$H$67,'Chart of Accounts'!$I$6:$I$67),"GL not found")} -> GL not found | H3: 925000 | I3: Output tax review | J3: Truck It In (Private) Limited | K3: Customer invoice INV-250731 | L3: Approved | M3: Non-cash
A4: NB-002 | B4: 45869 | C4: Unpaid supplier bill - carrier services | D4: 1054 | E4: {=IFERROR(XLOOKUP(D4,'Chart of Accounts'!$H$6:$H$67,'Chart of Accounts'!$I$6:$I$67),"GL not found")} -> GL not found | F4: 1035 | G4: {=IFERROR(XLOOKUP(F4,'Chart of Accounts'!$H$6:$H$67,'Chart of Accounts'!$I$6:$I$67),"GL not found")} -> GL not found | H4: 315000 | I4: WHT review | J4: Truck It In (Private) Limited | K4: Supplier bill BILL-250731 | L4: Approved | M4: Non-cash
A5: NB-003 | B5: 45869 | C5: Month-end utilities accrual | D5: 1058 | E5: {=IFERROR(XLOOKUP(D5,'Chart of Accounts'!$H$6:$H$67,'Chart of Accounts'!$I$6:$I$67),"GL not found")} -> GL not found | F5: 1035 | G5: {=IFERROR(XLOOKUP(F5,'Chart of Accounts'!$H$6:$H$67,'Chart of Accounts'!$I$6:$I$67),"GL not found")} -> GL not found | H5: 85000 | I5: Input tax review | J5: Truck It In (Private) Limited | K5: Accrual schedule | L5: Approved | M5: Non-cash
A6: NB-004 | B6: 45869 | C6: One month insurance expense released from prepayment | D6: 1068 | E6: {=IFERROR(XLOOKUP(D6,'Chart of Accounts'!$H$6:$H$67,'Chart of Accounts'!$I$6:$I$67),"GL not found")} -> GL not found | F6: 1026 | G6: {=IFERROR(XLOOKUP(F6,'Chart of Accounts'!$H$6:$H$67,'Chart of Accounts'!$I$6:$I$67),"GL not found")} -> GL not found | H6: 15000 | I6: N/A | J6: Truck It In (Private) Limited | K6: Insurance amortization schedule | L6: Approved | M6: Non-cash
A7: NB-005 | B7: 45869 | C7: Monthly depreciation on equipment | D7: 1064 | E7: {=IFERROR(XLOOKUP(D7,'Chart of Accounts'!$H$6:$H$67,'Chart of Accounts'!$I$6:$I$67),"GL not found")} -> GL not found | F7: 1017 | G7: {=IFERROR(XLOOKUP(F7,'Chart of Accounts'!$H$6:$H$67,'Chart of Accounts'!$I$6:$I$67),"GL not found")} -> GL not found | H7: 120000 | I7: N/A | J7: Truck It In (Private) Limited | K7: Fixed asset register | L7: Approved | M7: Non-cash
A8: NB-006 | B8: 45869 | C8: Payroll expense accrued but unpaid | D8: 1056 | E8: {=IFERROR(XLOOKUP(D8,'Chart of Accounts'!$H$6:$H$67,'Chart of Accounts'!$I$6:$I$67),"GL not found")} -> GL not found | F8: 1034 | G8: {=IFERROR(XLOOKUP(F8,'Chart of Accounts'!$H$6:$H$67,'Chart of Accounts'!$I$6:$I$67),"GL not found")} -> GL not found | H8: 290000 | I8: Payroll | J8: Truck It In (Private) Limited | K8: Payroll register | L8: Approved | M8: Non-cash
A9: NB-007 | B9: 45869 | C9: Current income tax provision | D9: 1048 | E9: {=IFERROR(XLOOKUP(D9,'Chart of Accounts'!$H$6:$H$67,'Chart of Accounts'!$I$6:$I$67),"GL not found")} -> GL not found | F9: 1047 | G9: {=IFERROR(XLOOKUP(F9,'Chart of Accounts'!$H$6:$H$67,'Chart of Accounts'!$I$6:$I$67),"GL not found")} -> GL not found | H9: 140000 | I9: Current tax | J9: Truck It In (Private) Limited | K9: Tax computation | L9: Approved | M9: Non-cash

Sheet Journal Entries
A1: Journal Entries — Formula Linked
A2: JE ID | B2: Date | C2: Source | D2: Source Reference | E2: Description | F2: GL Code | G2: GL Account | H2: Debit | I2: Credit | J2: Entity | K2: Tax Treatment | L2: Posting Status | M2: Cash Flow Category
A3: ="JE-001" -> JE-001 | B3: ='Transaction Mapping'!C3 -> 45839 | C3: ="Bank Statement" -> Bank Statement | D3: ='Transaction Mapping'!E3 -> HBL250701001 | E3: ='Transaction Mapping'!D3 -> IBFT CR - Daraz Pakistan settlement INV-DZ-250701 | F3: ='Transaction Mapping'!K3 -> 1029 | G3: ='Transaction Mapping'!L3 -> GL not found | H3: =IF('Transaction Mapping'!G3>0,'Transaction Mapping'!G3,0) -> 685000 | I3: =IF('Transaction Mapping'!F3>0,'Transaction Mapping'!F3,0) -> 0 | J3: ='Transaction Mapping'!P3 -> Truck It In (Private) Limited | K3: ='Transaction Mapping'!O3 -> N/A | L3: ="Posted" -> Posted | M3: ='Transaction Mapping'!T3 -> Operating - Receipts
A4: ="JE-001" -> JE-001 | B4: ='Transaction Mapping'!C3 -> 45839 | C4: ="Bank Statement" -> Bank Statement | D4: ='Transaction Mapping'!E3 -> HBL250701001 | E4: ='Transaction Mapping'!D3 -> IBFT CR - Daraz Pakistan settlement INV-DZ-250701 | F4: ='Transaction Mapping'!M3 -> 1018 | G4: ='Transaction Mapping'!N3 -> GL not found | H4: =IF('Transaction Mapping'!F3>0,'Transaction Mapping'!F3,0) -> 0 | I4: =IF('Transaction Mapping'!G3>0,'Transaction Mapping'!G3,0) -> 685000 | J4: ='Transaction Mapping'!P3 -> Truck It In (Private) Limited | K4: ='Transaction Mapping'!O3 -> N/A | L4: ="Posted" -> Posted | M4: ='Transaction Mapping'!T3 -> Operating - Receipts
A5: ="JE-002" -> JE-002 | B5: ='Transaction Mapping'!C4 -> 45839 | C5: ="Bank Statement" -> Bank Statement | D5: ='Transaction Mapping'!E4 -> HBL250701002 | E5: ='Transaction Mapping'!D4 -> Online transfer - Office rent July - Blue Area Properties | F5: ='Transaction Mapping'!K4 -> 1029 | G5: ='Transaction Mapping'!L4 -> GL not found | H5: =IF('Transaction Mapping'!G4>0,'Transaction Mapping'!G4,0) -> 0 | I5: =IF('Transaction Mapping'!F4>0,'Transaction Mapping'!F4,0) -> 275000 | J5: ='Transaction Mapping'!P4 -> Truck It In (Private) Limited | K5: ='Transaction Mapping'!O4 -> Input tax review | L5: ="Posted" -> Posted | M5: ='Transaction Mapping'!T4 -> Operating - Payments
A6: ="JE-002" -> JE-002 | B6: ='Transaction Mapping'!C4 -> 45839 | C6: ="Bank Statement" -> Bank Statement | D6: ='Transaction Mapping'!E4 -> HBL250701002 | E6: ='Transaction Mapping'!D4 -> Online transfer - Office rent July - Blue Area Properties | F6: ='Transaction Mapping'!M4 -> 1058 | G6: ='Transaction Mapping'!N4 -> GL not found | H6: =IF('Transaction Mapping'!F4>0,'Transaction Mapping'!F4,0) -> 275000 | I6: =IF('Transaction Mapping'!G4>0,'Transaction Mapping'!G4,0) -> 0 | J6: ='Transaction Mapping'!P4 -> Truck It In (Private) Limited | K6: ='Transaction Mapping'!O4 -> Input tax review | L6: ="Posted" -> Posted | M6: ='Transaction Mapping'!T4 -> Operating - Payments
A7: ="JE-003" -> JE-003 | B7: ='Transaction Mapping'!C5 -> 45840 | C7: ="Bank Statement" -> Bank Statement | D7: ='Transaction Mapping'!E5 -> HBL250702003 | E7: ='Transaction Mapping'!D5 -> Raast CR - Onic distribution collection Batch 0702 | F7: ='Transaction Mapping'!K5 -> 1029 | G7: ='Transaction Mapping'!L5 -> GL not found | H7: =IF('Transaction Mapping'!G5>0,'Transaction Mapping'!G5,0) -> 412500 | I7: =IF('Transaction Mapping'!F5>0,'Transaction Mapping'!F5,0) -> 0 | J7: ='Transaction Mapping'!P5 -> Truck It In (Private) Limited | K7: ='Transaction Mapping'!O5 -> N/A | L7: ="Posted" -> Posted | M7: ='Transaction Mapping'!T5 -> Operating - Receipts
A8: ="JE-003" -> JE-003 | B8: ='Transaction Mapping'!C5 -> 45840 | C8: ="Bank Statement" -> Bank Statement | D8: ='Transaction Mapping'!E5 -> HBL250702003 | E8: ='Transaction Mapping'!D5 -> Raast CR - Onic distribution collection Batch 0702 | F8: ='Transaction Mapping'!M5 -> 1018 | G8: ='Transaction Mapping'!N5 -> GL not found | H8: =IF('Transaction Mapping'!F5>0,'Transaction Mapping'!F5,0) -> 0 | I8: =IF('Transaction Mapping'!G5>0,'Transaction Mapping'!G5,0) -> 412500 | J8: ='Transaction Mapping'!P5 -> Truck It In (Private) Limited | K8: ='Transaction Mapping'!O5 -> N/A | L8: ="Posted" -> Posted | M8: ='Transaction Mapping'!T5 -> Operating - Receipts
A9: ="JE-004" -> JE-004 | B9: ='Transaction Mapping'!C6 -> 45840 | C9: ="Bank Statement" -> Bank Statement | D9: ='Transaction Mapping'!E6 -> HBL250702004 | E9: ='Transaction Mapping'!D6 -> POS 7712 - Shell F-8 Islamabad | F9: ='Transaction Mapping'!K6 -> 1029 | G9: ='Transaction Mapping'!L6 -> GL not found | H9: =IF('Transaction Mapping'!G6>0,'Transaction Mapping'!G6,0) -> 0 | I9: =IF('Transaction Mapping'!F6>0,'Transaction Mapping'!F6,0) -> 18450 | J9: ='Transaction Mapping'!P6 -> Truck It In (Private) Limited | K9: ='Transaction Mapping'!O6 -> Input tax review | L9: ="Posted" -> Posted | M9: ='Transaction Mapping'!T6 -> Operating - Payments
A10: ="JE-004" -> JE-004 | B10: ='Transaction Mapping'!C6 -> 45840 | C10: ="Bank Statement" -> Bank Statement | D10: ='Transaction Mapping'!E6 -> HBL250702004 | E10: ='Transaction Mapping'!D6 -> POS 7712 - Shell F-8 Islamabad | F10: ='Transaction Mapping'!M6 -> 1055 | G10: ='Transaction Mapping'!N6 -> GL not found | H10: =IF('Transaction Mapping'!F6>0,'Transaction Mapping'!F6,0) -> 18450 | I10: =IF('Transaction Mapping'!G6>0,'Transaction Mapping'!G6,0) -> 0 | J10: ='Transaction Mapping'!P6 -> Truck It In (Private) Limited | K10: ='Transaction Mapping'!O6 -> Input tax review | L10: ="Posted" -> Posted | M10: ='Transaction Mapping'!T6 -> Operating - Payments
A11: ="JE-005" -> JE-005 | B11: ='Transaction Mapping'!C7 -> 45841 | C11: ="Bank Statement" -> Bank Statement | D11: ='Transaction Mapping'!E7 -> CHQ104583 | E11: ='Transaction Mapping'!D7 -> Cheque 104583 - Pak Cargo Fleet Services | F11: ='Transaction Mapping'!K7 -> 1029 | G11: ='Transaction Mapping'!L7 -> GL not found | H11: =IF('Transaction Mapping'!G7>0,'Transaction Mapping'!G7,0) -> 0 | I11: =IF('Transaction Mapping'!F7>0,'Transaction Mapping'!F7,0) -> 335000 | J11: ='Transaction Mapping'!P7 -> Truck It In (Private) Limited | K11: ='Transaction Mapping'!O7 -> WHT applicable | L11: ="Posted" -> Posted | M11: ='Transaction Mapping'!T7 -> Operating - Payments
A12: ="JE-005" -> JE-005 | B12: ='Transaction Mapping'!C7 -> 45841 | C12: ="Bank Statement" -> Bank Statement | D12: ='Transaction Mapping'!E7 -> CHQ104583 | E12: ='Transaction Mapping'!D7 -> Cheque 104583 - Pak Cargo Fleet Services | F12: ='Transaction Mapping'!M7 -> 1054 | G12: ='Transaction Mapping'!N7 -> GL not found | H12: =IF('Transaction Mapping'!F7>0,'Transaction Mapping'!F7,0) -> 335000 | I12: =IF('Transaction Mapping'!G7>0,'Transaction Mapping'!G7,0) -> 0 | J12: ='Transaction Mapping'!P7 -> Truck It In (Private) Limited | K12: ='Transaction Mapping'!O7 -> WHT applicable | L12: ="Posted" -> Posted | M12: ='Transaction Mapping'!T7 -> Operating - Payments
A13: ="JE-006" -> JE-006 | B13: ='Transaction Mapping'!C8 -> 45841 | C13: ="Bank Statement" -> Bank Statement | D13: ='Transaction Mapping'!E8 -> WHT104583 | E13: ='Transaction Mapping'!D8 -> Withholding tax on cheque 104583 | F13: ='Transaction Mapping'!K8 -> 1029 | G13: ='Transaction Mapping'!L8 -> GL not found | H13: =IF('Transaction Mapping'!G8>0,'Transaction Mapping'!G8,0) -> 0 | I13: =IF('Transaction Mapping'!F8>0,'Transaction Mapping'!F8,0) -> 3350 | J13: ='Transaction Mapping'!P8 -> Truck It In (Private) Limited | K13: ='Transaction Mapping'!O8 -> Withholding tax | L13: ="Posted" -> Posted | M13: ='Transaction Mapping'!T8 -> Operating - Payments
A14: ="JE-006" -> JE-006 | B14: ='Transaction Mapping'!C8 -> 45841 | C14: ="Bank Statement" -> Bank Statement | D14: ='Transaction Mapping'!E8 -> WHT104583 | E14: ='Transaction Mapping'!D8 -> Withholding tax on cheque 104583 | F14: ='Transaction Mapping'!M8 -> 1036 | G14: ='Transaction Mapping'!N8 -> GL not found | H14: =IF('Transaction Mapping'!F8>0,'Transaction Mapping'!F8,0) -> 3350 | I14: =IF('Transaction Mapping'!G8>0,'Transaction Mapping'!G8,0) -> 0 | J14: ='Transaction Mapping'!P8 -> Truck It In (Private) Limited | K14: ='Transaction Mapping'!O8 -> Withholding tax | L14: ="Posted" -> Posted | M14: ='Transaction Mapping'!T8 -> Operating - Payments
A15: ="JE-007" -> JE-007 | B15: ='Transaction Mapping'!C9 -> 45842 | C15: ="Bank Statement" -> Bank Statement | D15: ='Transaction Mapping'!E9 -> HBL250704007 | E15: ='Transaction Mapping'!D9 -> IBFT CR - Sapphire merchant COD settlement | F15: ='Transaction Mapping'!K9 -> 1029 | G15: ='Transaction Mapping'!L9 -> GL not found | H15: =IF('Transaction Mapping'!G9>0,'Transaction Mapping'!G9,0) -> 298750 | I15: =IF('Transaction Mapping'!F9>0,'Transaction Mapping'!F9,0) -> 0 | J15: ='Transaction Mapping'!P9 -> Truck It In (Private) Limited | K15: ='Transaction Mapping'!O9 -> N/A | L15: ="Posted" -> Posted | M15: ='Transaction Mapping'!T9 -> Operating - Receipts
A16: ="JE-007" -> JE-007 | B16: ='Transaction Mapping'!C9 -> 45842 | C16: ="Bank Statement" -> Bank Statement | D16: ='Transaction Mapping'!E9 -> HBL250704007 | E16: ='Transaction Mapping'!D9 -> IBFT CR - Sapphire merchant COD settlement | F16: ='Transaction Mapping'!M9 -> 1018 | G16: ='Transaction Mapping'!N9 -> GL not found | H16: =IF('Transaction Mapping'!F9>0,'Transaction Mapping'!F9,0) -> 0 | I16: =IF('Transaction Mapping'!G9>0,'Transaction Mapping'!G9,0) -> 298750 | J16: ='Transaction Mapping'!P9 -> Truck It In (Private) Limited | K16: ='Transaction Mapping'!O9 -> N/A | L16: ="Posted" -> Posted | M16: ='Transaction Mapping'!T9 -> Operating - Receipts
A17: ="JE-008" -> JE-008 | B17: ='Transaction Mapping'!C10 -> 45842 | C17: ="Bank Statement" -> Bank Statement | D17: ='Transaction Mapping'!E10 -> HBL250704008 | E17: ='Transaction Mapping'!D10 -> Online payment - PTCL corporate internet June | F17: ='Transaction Mapping'!K10 -> 1029 | G17: ='Transaction Mapping'!L10 -> GL not found | H17: =IF('Transaction Mapping'!G10>0,'Transaction Mapping'!G10,0) -> 0 | I17: =IF('Transaction Mapping'!F10>0,'Transaction Mapping'!F10,0) -> 42800 | J17: ='Transaction Mapping'!P10 -> Truck It In (Private) Limited | K17: ='Transaction Mapping'!O10 -> Input tax review | L17: ="Posted" -> Posted | M17: ='Transaction Mapping'!T10 -> Operating - Payments
A18: ="JE-008" -> JE-008 | B18: ='Transaction Mapping'!C10 -> 45842 | C18: ="Bank Statement" -> Bank Statement | D18: ='Transaction Mapping'!E10 -> HBL250704008 | E18: ='Transaction Mapping'!D10 -> Online payment - PTCL corporate internet June | F18: ='Transaction Mapping'!M10 -> 1058 | G18: ='Transaction Mapping'!N10 -> GL not found | H18: =IF('Transaction Mapping'!F10>0,'Transaction Mapping'!F10,0) -> 42800 | I18: =IF('Transaction Mapping'!G10>0,'Transaction Mapping'!G10,0) -> 0 | J18: ='Transaction Mapping'!P10 -> Truck It In (Private) Limited | K18: ='Transaction Mapping'!O10 -> Input tax review | L18: ="Posted" -> Posted | M18: ='Transaction Mapping'!T10 -> Operating - Payments
A19: ="JE-009" -> JE-009 | B19: ='Transaction Mapping'!C11 -> 45843 | C19: ="Bank Statement" -> Bank Statement | D19: ='Transaction Mapping'!E11 -> ATM250705 | E19: ='Transaction Mapping'!D11 -> ATM cash withdrawal - HBL Blue Area | F19: ='Transaction Mapping'!K11 -> 1029 | G19: ='Transaction Mapping'!L11 -> GL not found | H19: =IF('Transaction Mapping'!G11>0,'Transaction Mapping'!G11,0) -> 0 | I19: =IF('Transaction Mapping'!F11>0,'Transaction Mapping'!F11,0) -> 50000 | J19: ='Transaction Mapping'!P11 -> Truck It In (Private) Limited | K19: ='Transaction Mapping'!O11 -> N/A | L19: ="Posted" -> Posted | M19: ='Transaction Mapping'!T11 -> Operating - Payments
A20: ="JE-009" -> JE-009 | B20: ='Transaction Mapping'!C11 -> 45843 | C20: ="Bank Statement" -> Bank Statement | D20: ='Transaction Mapping'!E11 -> ATM250705 | E20: ='Transaction Mapping'!D11 -> ATM cash withdrawal - HBL Blue Area | F20: ='Transaction Mapping'!M11 -> 1068 | G20: ='Transaction Mapping'!N11 -> GL not found | H20: =IF('Transaction Mapping'!F11>0,'Transaction Mapping'!F11,0) -> 50000 | I20: =IF('Transaction Mapping'!G11>0,'Transaction Mapping'!G11,0) -> 0 | J20: ='Transaction Mapping'!P11 -> Truck It In (Private) Limited | K20: ='Transaction Mapping'!O11 -> N/A | L20: ="Posted" -> Posted | M20: ='Transaction Mapping'!T11 -> Operating - Payments
A21: ="JE-010" -> JE-010 | B21: ='Transaction Mapping'!C12 -> 45845 | C21: ="Bank Statement" -> Bank Statement | D21: ='Transaction Mapping'!E12 -> HBL250707011 | E21: ='Transaction Mapping'!D12 -> Transfer to Meezan Bank payroll account | F21: ='Transaction Mapping'!K12 -> 1029 | G21: ='Transaction Mapping'!L12 -> GL not found | H21: =IF('Transaction Mapping'!G12>0,'Transaction Mapping'!G12,0) -> 0 | I21: =IF('Transaction Mapping'!F12>0,'Transaction Mapping'!F12,0) -> 850000 | J21: ='Transaction Mapping'!P12 -> Truck It In (Private) Limited | K21: ='Transaction Mapping'!O12 -> N/A | L21: ="Posted" -> Posted | M21: ='Transaction Mapping'!T12 -> Transfer
A22: ="JE-010" -> JE-010 | B22: ='Transaction Mapping'!C12 -> 45845 | C22: ="Bank Statement" -> Bank Statement | D22: ='Transaction Mapping'!E12 -> HBL250707011 | E22: ='Transaction Mapping'!D12 -> Transfer to Meezan Bank payroll account | F22: ='Transaction Mapping'!M12 -> 1030 | G22: ='Transaction Mapping'!N12 -> GL not found | H22: =IF('Transaction Mapping'!F12>0,'Transaction Mapping'!F12,0) -> 850000 | I22: =IF('Transaction Mapping'!G12>0,'Transaction Mapping'!G12,0) -> 0 | J22: ='Transaction Mapping'!P12 -> Truck It In (Private) Limited | K22: ='Transaction Mapping'!O12 -> N/A | L22: ="Posted" -> Posted | M22: ='Transaction Mapping'!T12 -> Transfer
